<?xml version="1.0"?>
<robot xmlns:xacro="http://ros.org/wiki/xacro" name="omniwheel">

  <xacro:macro name="omniwheel" params="parent *joint_pose">

    <link name="omniwheel_Link">
      <inertial>
        <origin xyz="0 0 0" rpy="0 0 0" />
        <mass value="0.028591" />
        <inertia
          ixx="4.812E-06" ixy="-1.630E-16" ixz="3.9705E-22"
          iyy="5.447E-06" iyz="5.7548E-17"
          izz="4.8098E-06" />
      </inertial>
      <visual>
        <origin xyz="0 0 0" rpy="0 0 0" />
        <geometry>
          <mesh filename="${path_meshes}/omniwheel/omniwheel_Link.STL" />
        </geometry>
        <material name="DarkGrey" />
      </visual>
      <collision>
        <origin xyz="0 0 0" rpy="0 0 0" />
        <geometry>
          <sphere radius="0.021"/>
        </geometry>
      </collision>
    </link>

    <gazebo reference="omniwheel_link">
      <mu1 value="1.0"/>
      <mu2 value="1.0"/>
      <kp value="10000000.0" />
      <kd value="1.0" />
      <fdir1 value="1 0 0"/>
      <maxContacts>1</maxContacts>
      <material>Gazebo/Black</material>
    </gazebo>

    <joint name="omniwheel" type="continuous">
      <xacro:insert_block name="joint_pose"/>
      <parent link="${parent}" />
      <child link="omniwheel_Link" />
      <axis xyz="0 -1 0" />
      <mimic joint="Left" multiplier="1" offset="0"/>
    </joint>

  </xacro:macro>

</robot>
