<?xml version="1.0"?>
<robot xmlns:xacro="http://ros.org/wiki/xacro" name="dude_wheel">	
  
  <xacro:macro name="banebots_wheel" params="position reflect *joint_pose">
  
    <link name="${position}_wheel_link">

      <visual>
        <origin xyz="0 0 0" rpy="${M_PI/2} 0 0" />
          <geometry>
            <mesh filename="${path_meshes}/wheel/wheel_link.STL" />
          </geometry>
          <material name="Blue" />
      </visual>
      <collision>
        <origin xyz="0 0 0" rpy="0 0 0" />
        <geometry>
          <cylinder length="${wheel_leght}" radius="${wheel_radius}"/>
        </geometry>
      </collision>
      <inertial>
        <origin xyz="0 0 0" rpy="${M_PI/2} 0 0" />
        <mass value="0.0372140206710188" />
        <inertia
          ixx="1.12116949143941E-05" ixy="0" ixz="0"
          iyy="2.18923205916391E-05" iyz="0"
          izz="1.12116949143941E-05" />
      </inertial>
    </link>

    <gazebo reference="${position}_wheel_link">
      <mu1 value="1.0"/>
      <mu2 value="1.0"/>
      <kp value="10000000.0" />
      <kd value="1.0" />
      <fdir1 value="1 0 0"/>
      <maxContacts>1</maxContacts>
      <material>Gazebo/Blue</material>
    </gazebo>

    <joint name="${position}" type="continuous">      
      <parent link="base_link"/>
      <child link="${position}_wheel_link"/>
      <limit effort="12" velocity="25"/>
      <joint_properties damping="0.0" friction="0.0"/>
      <xacro:insert_block name="joint_pose"/>
      <axis xyz="0 0 ${reflect}"/>
    </joint>

    <transmission name="${position}_trans" type="SimpleTransmission">
      <type>transmission_interface/SimpleTransmission</type>
      <actuator name="${position}_motor">
        <mechanicalReduction>1</mechanicalReduction>
      </actuator>
      <joint name="${position}">
        <hardwareInterface>VelocityJointInterface</hardwareInterface>
      </joint>
    </transmission>

  </xacro:macro>

</robot>
